Traceback (most recent call last):
  File "Auto-opener.py", line 5, in <module>
  File "gui.pyc", line 222, in run_gui
  File "gui.pyc", line 125, in __init__
  File "PIL\ImageTk.pyc", line 89, in __init__
  File "PIL\ImageTk.pyc", line 58, in _get_image_from_kw
  File "PIL\Image.pyc", line 2975, in open
FileNotFoundError: [Errno 2] No such file or directory: 'D:\\Miscellanea\\Programmig\\Programming-Python\\Projects_Training\\Auto_opener\\Auto_opener\\data\\image\\adding.png'
Exception ignored in: <function PhotoImage.__del__ at 0x02AD8F10>
Traceback (most recent call last):
  File "PIL\ImageTk.pyc", line 118, in __del__
AttributeError: 'PhotoImage' object has no attribute '_PhotoImage__photo'
Traceback (most recent call last):
  File "Auto-opener.py", line 5, in <module>
  File "gui.pyc", line 222, in run_gui
  File "gui.pyc", line 125, in __init__
  File "PIL\ImageTk.pyc", line 89, in __init__
  File "PIL\ImageTk.pyc", line 58, in _get_image_from_kw
  File "PIL\Image.pyc", line 2975, in open
FileNotFoundError: [Errno 2] No such file or directory: 'D:\\Miscellanea\\Programmig\\Programming-Python\\Projects_Training\\Auto_opener\\Auto_opener\\data\\image\\adding.png'
Exception ignored in: <function PhotoImage.__del__ at 0x02AD8F10>
Traceback (most recent call last):
  File "PIL\ImageTk.pyc", line 118, in __del__
AttributeError: 'PhotoImage' object has no attribute '_PhotoImage__photo'
Exception in Tkinter callback
Traceback (most recent call last):
  File "psutil\_common.pyc", line 447, in wrapper
AttributeError: _cache

During handling of the above exception, another exception occurred:

Traceback (most recent call last):
  File "psutil\_pswindows.pyc", line 679, in wrapper
  File "psutil\_common.pyc", line 450, in wrapper
  File "psutil\_pswindows.pyc", line 766, in exe
PermissionError: [WinError 24] Длина выданной программой команды слишком велика: '(originated from NtQuerySystemInformation)'

During handling of the above exception, another exception occurred:

Traceback (most recent call last):
  File "tkinter\__init__.pyc", line 1883, in __call__
  File "gui.pyc", line 192, in <lambda>
  File "path_commands.pyc", line 154, in close
  File "path_commands.pyc", line 77, in deleting_processes
  File "path_commands.pyc", line 78, in <setcomp>
  File "psutil\__init__.pyc", line 617, in name
  File "psutil\_pswindows.pyc", line 750, in name
  File "psutil\_pswindows.pyc", line 681, in wrapper
psutil.AccessDenied: psutil.AccessDenied (pid=6592)
Exception in Tkinter callback
Traceback (most recent call last):
  File "psutil\_common.pyc", line 447, in wrapper
AttributeError: _cache

During handling of the above exception, another exception occurred:

Traceback (most recent call last):
  File "psutil\_pswindows.pyc", line 679, in wrapper
  File "psutil\_common.pyc", line 450, in wrapper
  File "psutil\_pswindows.pyc", line 766, in exe
PermissionError: [WinError 24] Длина выданной программой команды слишком велика: '(originated from NtQuerySystemInformation)'

During handling of the above exception, another exception occurred:

Traceback (most recent call last):
  File "tkinter\__init__.pyc", line 1883, in __call__
  File "gui.pyc", line 192, in <lambda>
  File "path_commands.pyc", line 154, in close
  File "path_commands.pyc", line 77, in deleting_processes
  File "path_commands.pyc", line 78, in <setcomp>
  File "psutil\__init__.pyc", line 617, in name
  File "psutil\_pswindows.pyc", line 750, in name
  File "psutil\_pswindows.pyc", line 681, in wrapper
psutil.AccessDenied: psutil.AccessDenied (pid=6592)
Exception in Tkinter callback
Traceback (most recent call last):
  File "psutil\_common.pyc", line 447, in wrapper
AttributeError: _cache

During handling of the above exception, another exception occurred:

Traceback (most recent call last):
  File "psutil\_pswindows.pyc", line 679, in wrapper
  File "psutil\_common.pyc", line 450, in wrapper
  File "psutil\_pswindows.pyc", line 766, in exe
PermissionError: [WinError 24] Длина выданной программой команды слишком велика: '(originated from NtQuerySystemInformation)'

During handling of the above exception, another exception occurred:

Traceback (most recent call last):
  File "tkinter\__init__.pyc", line 1883, in __call__
  File "gui.pyc", line 192, in <lambda>
  File "path_commands.pyc", line 154, in close
  File "path_commands.pyc", line 77, in deleting_processes
  File "path_commands.pyc", line 78, in <setcomp>
  File "psutil\__init__.pyc", line 617, in name
  File "psutil\_pswindows.pyc", line 750, in name
  File "psutil\_pswindows.pyc", line 681, in wrapper
psutil.AccessDenied: psutil.AccessDenied (pid=6364)
Exception in Tkinter callback
Traceback (most recent call last):
  File "psutil\_common.pyc", line 447, in wrapper
AttributeError: _cache

During handling of the above exception, another exception occurred:

Traceback (most recent call last):
  File "psutil\_pswindows.pyc", line 679, in wrapper
  File "psutil\_common.pyc", line 450, in wrapper
  File "psutil\_pswindows.pyc", line 766, in exe
PermissionError: [WinError 24] Длина выданной программой команды слишком велика: '(originated from NtQuerySystemInformation)'

During handling of the above exception, another exception occurred:

Traceback (most recent call last):
  File "tkinter\__init__.pyc", line 1883, in __call__
  File "gui.pyc", line 192, in <lambda>
  File "path_commands.pyc", line 154, in close
  File "path_commands.pyc", line 77, in deleting_processes
  File "path_commands.pyc", line 78, in <setcomp>
  File "psutil\__init__.pyc", line 617, in name
  File "psutil\_pswindows.pyc", line 750, in name
  File "psutil\_pswindows.pyc", line 681, in wrapper
psutil.AccessDenied: psutil.AccessDenied (pid=6496)
Exception in Tkinter callback
Traceback (most recent call last):
  File "tkinter\__init__.pyc", line 1883, in __call__
  File "gui.pyc", line 181, in <lambda>
  File "path_commands.pyc", line 125, in adding_path
  File "path_commands.pyc", line 38, in update_start_message
KeyError: 'Text_1'
Exception in Tkinter callback
Traceback (most recent call last):
  File "psutil\_common.pyc", line 447, in wrapper
AttributeError: _cache

During handling of the above exception, another exception occurred:

Traceback (most recent call last):
  File "psutil\_pswindows.pyc", line 679, in wrapper
  File "psutil\_common.pyc", line 450, in wrapper
  File "psutil\_pswindows.pyc", line 766, in exe
PermissionError: [WinError 24] Длина выданной программой команды слишком велика: '(originated from NtQuerySystemInformation)'

During handling of the above exception, another exception occurred:

Traceback (most recent call last):
  File "tkinter\__init__.pyc", line 1883, in __call__
  File "gui.pyc", line 192, in <lambda>
  File "path_commands.pyc", line 154, in close
  File "path_commands.pyc", line 77, in deleting_processes
  File "path_commands.pyc", line 78, in <setcomp>
  File "psutil\__init__.pyc", line 617, in name
  File "psutil\_pswindows.pyc", line 750, in name
  File "psutil\_pswindows.pyc", line 681, in wrapper
psutil.AccessDenied: psutil.AccessDenied (pid=3864)
